<?xml version="1.0"?>
<!-- created with Phobos 1.0.1 "Capricious Choutengan" -->
<robot name="roverB" xmlns:xacro="http://wiki.ros.org/xacro">

  <link name="base_footprint"></link>
  <joint name="base_footprint_joint_" type="fixed">
    <origin xyz="0 0 1.5" rpy="0 0 0" />
    <parent link="base_footprint" />
    <child link="base_link" />
  </joint>
  <link name="base_link"></link>
  <joint name="base_link_joint_" type="fixed">
    <origin xyz="0 0 0" rpy="0 0 1.57" />
    <parent link="base_link" />
    <child link="robot" />
  </joint>

  <link name="P_abajo">
    <inertial>
      <origin xyz="0 0 0" rpy="0 0 0" />
      <mass value="0.001" />
      <inertia ixx="0.001" ixy="0" ixz="0" iyy="0.001" iyz="0" izz="0.001" />
    </inertial>
    <collision name="Cube.006">
      <origin xyz="0 0 0.01283" rpy="0 0 0" />
      <geometry>
        <box size="1.67 2.0 0.001" />
      </geometry>
    </collision>
  </link>

  <link name="P_atras">
    <inertial>
      <origin xyz="0 0 0" rpy="0 0 0" />
      <mass value="0.001" />
      <inertia ixx="0.001" ixy="0" ixz="0" iyy="0.001" iyz="0" izz="0.001" />
    </inertial>
    <collision name="Plane">
      <origin xyz="0 0 0" rpy="0 0 0" />
      <geometry>
        <box size="1.8 1.36 0" />
      </geometry>
    </collision>
  </link>

  <link name="P_derecha">
    <inertial>
      <origin xyz="0 0 0" rpy="0 0 0" />
      <mass value="0.001" />
      <inertia ixx="0.001" ixy="0" ixz="0" iyy="0.001" iyz="0" izz="0.001" />
    </inertial>
    <collision name="Plane">
      <origin xyz="0 0 0" rpy="0 0 0" />
      <geometry>
        <box size="1.77 1.13 0" />
      </geometry>
    </collision>
  </link>


  <link name="Untitled">
    <inertial>
      <origin xyz="0 0 0" rpy="0 0 0" />
      <mass value="0.001" />
      <inertia ixx="0.001" ixy="0" ixz="0" iyy="0.001" iyz="0" izz="0.001" />
    </inertial>
    <collision name="Plane">
      <origin xyz="0 0 0" rpy="0 0 0" />
      <geometry>
        <box size="1.41 2.2 0" />
      </geometry>
    </collision>
  </link>

  <link name="Untitled.001">
    <inertial>
      <origin xyz="0 0 0" rpy="0 0 0" />
      <mass value="0.001" />
      <inertia ixx="0.001" ixy="0" ixz="0" iyy="0.001" iyz="0" izz="0.001" />
    </inertial>
    <collision name="Plane">
      <origin xyz="0 0 0" rpy="0 0 0" />
      <geometry>
        <box size="1.71 1.28 0" />
      </geometry>
    </collision>
  </link>

  <link name="robot">
    <inertial>
      <origin xyz="0 0 -0.0021" rpy="0 0 0" />
      <mass value="500.0" />
      <inertia ixx="114.54339" ixy="2.59267" ixz="-7.60408" iyy="45.98467" iyz="7.01369"
        izz="128.17601" />
    </inertial>
    <visual name="car">
      <origin xyz="0 0 0" rpy="0 0 0" />
      <geometry>
        <mesh filename="file://$(find robot_description)/meshes/dae/Cube.dae"
          scale="1.0 1.715 0.78246" />
      </geometry>
      <material name="Material" />
    </visual>
  </link>

  <link name="rueda1">
    <inertial>
      <origin xyz="0 0 0" rpy="0 0 0" />
      <mass value="10.0" />
      <inertia ixx="0.18726" ixy="0" ixz="0" iyy="0.09682" iyz="0" izz="3.78202" />
    </inertial>
    <visual name="rueda3.001">
      <origin xyz="0 0 0" rpy="0 0 0" />
      <geometry>
        <mesh filename="file://$(find robot_description)/meshes/dae/Torus.007.dae"
          scale="0.4 0.4 1.0" />
      </geometry>
      <material name="rueda" />
    </visual>
    <collision name="rueda3.001.000">
      <origin xyz="0 0 0" rpy="0 0 0" />
      <geometry>
        <mesh filename="file://$(find robot_description)/meshes/dae/Torus.001.dae"
          scale="1.0 1.0 1.0" />
      </geometry>
    </collision>
  </link>

  <link name="rueda2">
    <inertial>
      <origin xyz="0 0 0" rpy="0 0 0" />
      <mass value="10.0" />
      <inertia ixx="1.17034" ixy="0" ixz="0" iyy="0.70986" iyz="0" izz="0.70986" />
    </inertial>
    <visual name="rueda4.001">
      <origin xyz="0 0 0" rpy="0 0 0" />
      <geometry>
        <mesh filename="file://$(find robot_description)/meshes/dae/Torus.008.dae"
          scale="0.4 0.4 1.0" />
      </geometry>
      <material name="rueda" />
    </visual>
    <collision name="rueda4.001.000">
      <origin xyz="0 0 0" rpy="0 0 0" />
      <geometry>
        <mesh filename="file://$(find robot_description)/meshes/dae/Torus.000.dae"
          scale="1.0 1.0 1.0" />
      </geometry>
    </collision>
  </link>

  <link name="rueda3">
    <inertial>
      <origin xyz="0 0 0" rpy="0 0 0" />
      <mass value="10.0" />
      <inertia ixx="1.17034" ixy="0" ixz="0" iyy="0.70986" iyz="0" izz="0.70986" />
    </inertial>
    <visual name="rueda2.001">
      <origin xyz="0 0 0" rpy="0 0 0" />
      <geometry>
        <mesh filename="file://$(find robot_description)/meshes/dae/Torus.003.dae"
          scale="0.4 0.4 1.0" />
      </geometry>
      <material name="rueda" />
    </visual>
    <collision name="rueda2.001.000">
      <origin xyz="0 0 0" rpy="0 0 0" />
      <geometry>
        <mesh filename="file://$(find robot_description)/meshes/dae/Torus.004.dae"
          scale="1.0 1.0 1.0" />
      </geometry>
    </collision>
  </link>

  <link name="rueda4">
    <inertial>
      <origin xyz="0 0 0" rpy="0 0 0" />
      <mass value="10.0" />
      <inertia ixx="1.17034" ixy="0" ixz="0" iyy="0.70986" iyz="0" izz="0.70986" />
    </inertial>
    <visual name="rueda1.001">
      <origin xyz="0 0 0" rpy="0 0 0" />
      <geometry>
        <mesh filename="file://$(find robot_description)/meshes/dae/Torus.006.dae"
          scale="0.4 0.4 1.0" />
      </geometry>
      <material name="rueda" />
    </visual>
    <collision name="rueda1.001.000">
      <origin xyz="0 0 0" rpy="0 0 0" />
      <geometry>
        <mesh filename="/$(find robot_description)/meshes/dae/Torus.002.dae" scale="1.0 1.0 1.0" />
      </geometry>
    </collision>
  </link>


  <joint name="P_abajo_" type="fixed">
    <origin xyz="-0.13097 0.46899 -0.78586" rpy="0 0 0" />
    <parent link="robot" />
    <child link="P_abajo" />
  </joint>

  <joint name="P_atras_" type="fixed">
    <origin xyz="0.00012 1.51088 0.10075" rpy="1.5708 0 0" />
    <parent link="robot" />
    <child link="P_atras" />
  </joint>

  <joint name="P_derecha_" type="fixed">
    <origin xyz="-0.7846 0.50205 0.06662" rpy="1.5708 0 1.5708" />
    <parent link="robot" />
    <child link="P_derecha" />
  </joint>

  <joint name="Untitled_" type="fixed">
    <origin xyz="0.81387 0.60732 -0.01647" rpy="0 1.5708 0" />
    <parent link="robot" />
    <child link="Untitled" />
  </joint>

  <joint name="Untitled.001_" type="fixed">
    <origin xyz="0.04728 -0.52958 0.01956" rpy="1.5708 0 0" />
    <parent link="robot" />
    <child link="Untitled.001" />
  </joint>

  <joint name="rueda1_" type="continuous">
    <origin xyz="1.5 1.47 -1.17" rpy="0 1.5708 0" />
    <parent link="robot" />
    <child link="rueda1" />
    <axis xyz="0 0 1.0" />
    <limit effort="0" velocity="0" />
  </joint>

  <joint name="rueda2_" type="continuous">
    <origin xyz="1.5 -1.47 -1.17" rpy="0 1.5708 0" />
    <parent link="robot" />
    <child link="rueda2" />
    <axis xyz="0 0 1.0" />
    <limit effort="0" velocity="0" />
  </joint>

  <joint name="rueda3_" type="continuous">
    <origin xyz="-1.5 1.47 -1.17" rpy="0 1.5708 0" />
    <parent link="robot" />
    <child link="rueda3" />
    <axis xyz="0 0 1.0" />
    <limit effort="0" velocity="0" />
  </joint>

  <joint name="rueda4_" type="continuous">
    <origin xyz="-1.5 -1.47 -1.17" rpy="0 1.5708 0" />
    <parent link="robot" />
    <child link="rueda4" />
    <axis xyz="0 0 1.0" />
    <limit effort="0" velocity="0" />
  </joint>

  <material name="Material">
    <color rgba="0.34709 0.24198 0.8 1.0" />
  </material>

  <material name="Material.001">
    <color rgba="0 0 0 1.0" />
  </material>

  <material name="Material.002">
    <color rgba="0 0 0 1.0" />
  </material>

  <material name="brazo">
    <color rgba="0.26936 0.6037 0.64 1.0" />
  </material>

  <material name="rueda">
    <color rgba="0.08037 0.08037 0.08037 1.0" />
  </material>

  <!-- sensors -->
  <xacro:include filename="$(find robot_description)/urdf/sensors.urdf.xacro" />
  <xacro:arg name="robot_ns" default="" />
  <xacro:arg name="prefix" default="" />

  <xacro:sensor_camera node_name="front_camera" node_namespace="$(arg robot_ns)"
    frame_prefix="$(arg prefix)front_camera_" parent="$(arg prefix)base_link">
    <origin xyz="1.73 0.0 -0.01" rpy="0 3.141592 0" />
  </xacro:sensor_camera>
  <xacro:sensor_imu ns="$(arg robot_ns)" prefix="$(arg prefix)imu_" parent="$(arg prefix)robot">
    <origin xyz="0.0 0.0 0.0" rpy="0 0 0" />
  </xacro:sensor_imu>

</robot>